<robot
  name="wheelchair_henry">
  <link
    name="wheelchair/base_link">
    <inertial>
      <origin
        xyz="0.53211 -9.4007E-05 0.52163"
        rpy="0 0 0" />
      <mass
        value="272.65" />
      <inertia
        ixx="34.793"
        ixy="-0.011261"
        ixz="-5.7617"
        iyy="44.037"
        iyz="-0.013729"
        izz="36.587" />
    </inertial>
    <visual>
      <origin
        xyz="0 0 0"
        rpy="0 0 0" />
      <geometry>
        <mesh
          filename="package://hrl_base_selection/urdf/wheelchair_henry/meshes/base_link.STL" />
      </geometry>
      <material
        name="">
        <color
          rgba="0.79216 0.81961 0.93333 1" />
      </material>
    </visual>
    <collision>
      <origin
        xyz="0 0 0"
        rpy="0 0 0" />
      <geometry>
        <mesh
          filename="package://wheelchair_henry/meshes/base_link.STL" />
      </geometry>
    </collision>
  </link>
  <link
    name="wheelchair/head_link">
    <visual>
      <origin
        xyz="0 0 0"
        rpy="0 0 0" />
      <geometry>
        <mesh
          filename="package://hrl_base_selection/urdf/wheelchair_henry/meshes/head_link.STL" />
      </geometry>
      <material
        name="">
        <color
          rgba="0.792156862745098 0.819607843137255 0.933333333333333 1" />
      </material>
    </visual>
    <collision>
      <origin
        xyz="0 0 0"
        rpy="0 0 0" />
      <geometry>
        <mesh
          filename="package://hrl_base_selection/urdf/wheelchair_henry/meshes/head_link.STL" />
      </geometry>
    </collision>
  </link>
  <joint
    name="wheelchair/origin_to_base_joint"
    type="fixed">
    <origin
      xyz="0.452 0.0 1.35"
      rpy="0. 0.1 0." />
    <parent
      link="wheelchair/base_link" />
    <child
      link="wheelchair/head_link" />
    <axis
      xyz="0 0 0" />
    <limit
      lower="-2"
      upper="2"
      effort="0"
      velocity="0" />
  </joint>
  <link
    name="wheelchair/neck_rotation">
    <visual>
      <origin
        xyz="0 0 0"
        rpy="0 0 0" />
      <geometry>
        <mesh
          filename="package://hrl_base_selection/urdf/wheelchair_henry/meshes/neck_link.STL" />
      </geometry>
      <material
        name="">
        <color
          rgba="0.792156862745098 0.819607843137255 0.933333333333333 1" />
      </material>
    </visual>
    <collision>
      <origin
        xyz="0 0 0"
        rpy="0 0 0" />
      <geometry>
        <mesh
          filename="package://hrl_base_selection/urdf/wheelchair_henry/meshes/neck_link.STL" />
      </geometry>
    </collision>
  </link>
  <joint
    name="wheelchair/head_neck_joint1"
    type="revolute">
    <origin
      xyz="-0.0254 0 -0.08509"
      rpy="-1.5708 1.1345 -3.1416" />
    <parent
      link="wheelchair/head_link" />
    <child
      link="wheelchair/neck_rotation" />
    <axis
      xyz="0 0 -1" />
    <limit
      lower="-2"
      upper="2"
      effort="0"
      velocity="0" />
  </joint>
  <link
    name="wheelchair/neck_link">
    <visual>
      <origin
        xyz="0 0 0"
        rpy="0 0 0" />
      <geometry>
        <mesh
          filename="package://hrl_base_selection/urdf/wheelchair_henry/meshes/neck_link.STL" />
      </geometry>
      <material
        name="">
        <color
          rgba="0.792156862745098 0.819607843137255 0.933333333333333 1" />
      </material>
    </visual>
    <collision>
      <origin
        xyz="0 0 0"
        rpy="0 0 0" />
      <geometry>
        <mesh
          filename="package://hrl_base_selection/urdf/wheelchair_henry/meshes/neck_link.STL" />
      </geometry>
    </collision>
  </link>
  <joint
    name="wheelchair/head_neck_joint2"
    type="revolute">
    <origin
      xyz="0 0 0"
      rpy="0 3.1554E-30 0" />
    <parent
      link="wheelchair/neck_rotation" />
    <child
      link="wheelchair/neck_link" />
    <axis
      xyz="0 0 1" />
    <limit
      lower="-2"
      upper="2"
      effort="0"
      velocity="0" />
  </joint>
  <link
    name="wheelchair/upper_body_link">
    <visual>
      <origin
        xyz="0 0 0"
        rpy="0 0 0" />
      <geometry>
        <mesh
          filename="package://hrl_base_selection/urdf/wheelchair_henry/meshes/upper_body_link.STL" />
      </geometry>
      <material
        name="">
        <color
          rgba="0.792156862745098 0.819607843137255 0.933333333333333 1" />
      </material>
    </visual>
    <collision>
      <origin
        xyz="0 0 0"
        rpy="0 0 0" />
      <geometry>
        <mesh
          filename="package://hrl_base_selection/urdf/wheelchair_henry/meshes/upper_body_link.STL" />
      </geometry>
    </collision>
  </link>
  <joint
    name="wheelchair/neck_body_joint"
    type="revolute">
    <origin
      xyz="0.07239 0 0"
      rpy="-8.8242E-17 -8.2927E-14 0.66506" />
    <parent
      link="wheelchair/neck_link" />
    <child
      link="wheelchair/upper_body_link" />
    <axis
      xyz="0 0 -1" />
    <limit
      lower="-2"
      upper="2"
      effort="0"
      velocity="0" />
  </joint>
  <link
    name="wheelchair/mid_body_link">
    <visual>
      <origin
        xyz="0 0 0"
        rpy="0 0 0" />
      <geometry>
        <mesh
          filename="package://hrl_base_selection/urdf/wheelchair_henry/meshes/mid_body_link.STL" />
      </geometry>
      <material
        name="">
        <color
          rgba="0.792156862745098 0.819607843137255 0.933333333333333 1" />
      </material>
    </visual>
    <collision>
      <origin
        xyz="0 0 0"
        rpy="0 0 0" />
      <geometry>
        <mesh
          filename="package://hrl_base_selection/urdf/wheelchair_henry/meshes/mid_body_link.STL" />
      </geometry>
    </collision>
  </link>
  <joint
    name="wheelchair/upper_mid_body_joint"
    type="revolute">
    <origin
      xyz="0.35052 0 0"
      rpy="2.8327E-14 7.7949E-14 0.34907" />
    <parent
      link="wheelchair/upper_body_link" />
    <child
      link="wheelchair/mid_body_link" />
    <axis
      xyz="0 0 -1" />
    <limit
      lower="-2"
      upper="2"
      effort="0"
      velocity="0" />
  </joint>
  <link
    name="wheelchair/lower_body_link">
    <visual>
      <origin
        xyz="0 0 0"
        rpy="0 0 0" />
      <geometry>
        <mesh
          filename="package://hrl_base_selection/urdf/wheelchair_henry/meshes/lower_body_link.STL" />
      </geometry>
      <material
        name="">
        <color
          rgba="0.792156862745098 0.819607843137255 0.933333333333333 1" />
      </material>
    </visual>
    <collision>
      <origin
        xyz="0 0 0"
        rpy="0 0 0" />
      <geometry>
        <mesh
          filename="package://hrl_base_selection/urdf/wheelchair_henry/meshes/lower_body_link.STL" />
      </geometry>
    </collision>
  </link>
  <joint
    name="wheelchair/mid_lower_body_joint"
    type="revolute">
    <origin
      xyz="0.15113 0 0"
      rpy="-4.3091E-16 1.669E-15 -0.57779" />
    <parent
      link="wheelchair/mid_body_link" />
    <child
      link="wheelchair/lower_body_link" />
    <axis
      xyz="0 0 -1" />
    <limit
      lower="-2"
      upper="2"
      effort="0"
      velocity="0" />
  </joint>
  <link
    name="wheelchair/quad_left_link">
    <visual>
      <origin
        xyz="0 0 0"
        rpy="0 0 0" />
      <geometry>
        <mesh
          filename="package://hrl_base_selection/urdf/wheelchair_henry/meshes/quad_left_link.STL" />
      </geometry>
      <material
        name="">
        <color
          rgba="0.792156862745098 0.819607843137255 0.933333333333333 1" />
      </material>
    </visual>
    <collision>
      <origin
        xyz="0 0 0"
        rpy="0 0 0" />
      <geometry>
        <mesh
          filename="package://hrl_base_selection/urdf/wheelchair_henry/meshes/quad_left_link.STL" />
      </geometry>
    </collision>
  </link>
  <joint
    name="wheelchair/body_quad_left_joint"
    type="revolute">
    <origin
      xyz="0.05207 0 -0.08636"
      rpy="-3.1554E-30 -3.1554E-30 -2.7756E-17" />
    <parent
      link="wheelchair/lower_body_link" />
    <child
      link="wheelchair/quad_left_link" />
    <axis
      xyz="0 0 1" />
    <limit
      lower="-3."
      upper="3."
      effort="0"
      velocity="0" />
  </joint>
  <link
    name="wheelchair/calf_left_link">
    <visual>
      <origin
        xyz="0 0 0"
        rpy="0 0 0" />
      <geometry>
        <mesh
          filename="package://hrl_base_selection/urdf/wheelchair_henry/meshes/calf_left_link.STL" />
      </geometry>
      <material
        name="">
        <color
          rgba="0.792156862745098 0.819607843137255 0.933333333333333 1" />
      </material>
    </visual>
    <collision>
      <origin
        xyz="0 0 0"
        rpy="0 0 0" />
      <geometry>
        <mesh
          filename="package://hrl_base_selection/urdf/wheelchair_henry/meshes/calf_left_link.STL" />
      </geometry>
    </collision>
  </link>
  <joint
    name="wheelchair/quad_calf_left_joint"
    type="revolute">
    <origin
      xyz="0.41218 0.11044 0"
      rpy="3.1416 8.5469E-14 -2.8798" />
    <parent
      link="wheelchair/quad_left_link" />
    <child
      link="wheelchair/calf_left_link" />
    <axis
      xyz="0 0 1" />
    <limit
      lower="-3."
      upper="3."
      effort="0"
      velocity="0" />
  </joint>
  <link
    name="wheelchair/foot_left_link">
    <visual>
      <origin
        xyz="0 0 0"
        rpy="0 0 0" />
      <geometry>
        <mesh
          filename="package://hrl_base_selection/urdf/wheelchair_henry/meshes/foot_left_link.STL" />
      </geometry>
      <material
        name="">
        <color
          rgba="0.792156862745098 0.819607843137255 0.933333333333333 1" />
      </material>
    </visual>
    <collision>
      <origin
        xyz="0 0 0"
        rpy="0 0 0" />
      <geometry>
        <mesh
          filename="package://hrl_base_selection/urdf/wheelchair_henry/meshes/foot_left_link.STL" />
      </geometry>
    </collision>
  </link>
  <joint
    name="wheelchair/calf_foot_left_joint"
    type="revolute">
    <origin
      xyz="-0.41279 -0.03188 0"
      rpy="2.4608E-16 9.411E-16 0.077076" />
    <parent
      link="wheelchair/calf_left_link" />
    <child
      link="wheelchair/foot_left_link" />
    <axis
      xyz="0 0 1" />
    <limit
      lower="-3."
      upper="3."
      effort="0"
      velocity="0" />
  </joint>
  <link
    name="wheelchair/quad_right_link">
    <visual>
      <origin
        xyz="0 0 0"
        rpy="0 0 0" />
      <geometry>
        <mesh
          filename="package://hrl_base_selection/urdf/wheelchair_henry/meshes/quad_right_link.STL" />
      </geometry>
      <material
        name="">
        <color
          rgba="0.792156862745098 0.819607843137255 0.933333333333333 1" />
      </material>
    </visual>
    <collision>
      <origin
        xyz="0 0 0"
        rpy="0 0 0" />
      <geometry>
        <mesh
          filename="package://hrl_base_selection/urdf/wheelchair_henry/meshes/quad_right_link.STL" />
      </geometry>
    </collision>
  </link>
  <joint
    name="wheelchair/body_quad_right_joint"
    type="revolute">
    <origin
      xyz="0.05207 0 0.08636"
      rpy="-3.1554E-30 -3.1554E-30 -2.7756E-17" />
    <parent
      link="wheelchair/lower_body_link" />
    <child
      link="wheelchair/quad_right_link" />
    <axis
      xyz="0 0 1" />
    <limit
      lower="-3"
      upper="3"
      effort="0"
      velocity="0" />
  </joint>
  <link
    name="wheelchair/calf_right_link">
    <visual>
      <origin
        xyz="0 0 0"
        rpy="0 0 0" />
      <geometry>
        <mesh
          filename="package://hrl_base_selection/urdf/wheelchair_henry/meshes/calf_right_link.STL" />
      </geometry>
      <material
        name="">
        <color
          rgba="0.792156862745098 0.819607843137255 0.933333333333333 1" />
      </material>
    </visual>
    <collision>
      <origin
        xyz="0 0 0"
        rpy="0 0 0" />
      <geometry>
        <mesh
          filename="package://hrl_base_selection/urdf/wheelchair_henry/meshes/calf_right_link.STL" />
      </geometry>
    </collision>
  </link>
  <joint
    name="wheelchair/quad_calf_right_joint"
    type="revolute">
    <origin
      xyz="0.41218 0.11044 0"
      rpy="3.1416 8.5225E-14 -2.8798" />
    <parent
      link="wheelchair/quad_right_link" />
    <child
      link="wheelchair/calf_right_link" />
    <axis
      xyz="0 0 1" />
    <limit
      lower="-3"
      upper="3"
      effort="0"
      velocity="0" />
  </joint>
  <link
    name="wheelchair/foot_right_link">
    <visual>
      <origin
        xyz="0 0 0"
        rpy="0 0 0" />
      <geometry>
        <mesh
          filename="package://hrl_base_selection/urdf/wheelchair_henry/meshes/foot_right_link.STL" />
      </geometry>
      <material
        name="">
        <color
          rgba="0.792156862745098 0.819607843137255 0.933333333333333 1" />
      </material>
    </visual>
    <collision>
      <origin
        xyz="0 0 0"
        rpy="0 0 0" />
      <geometry>
        <mesh
          filename="package://hrl_base_selection/urdf/wheelchair_henry/meshes/foot_right_link.STL" />
      </geometry>
    </collision>
  </link>
  <joint
    name="wheelchair/calf_foot_right_joint"
    type="revolute">
    <origin
      xyz="-0.41279 -0.03188 0"
      rpy="3.3137E-27 3.7799E-26 0.077076" />
    <parent
      link="wheelchair/calf_right_link" />
    <child
      link="wheelchair/foot_right_link" />
    <axis
      xyz="0 0 1" />
    <limit
      lower="-3"
      upper="3"
      effort="0"
      velocity="0" />
  </joint>
  <link
    name="wheelchair/arm_left_link">
    <visual>
      <origin
        xyz="0 0 0"
        rpy="0 0 0" />
      <geometry>
        <mesh
          filename="package://hrl_base_selection/urdf/wheelchair_henry/meshes/arm_left_link.STL" />
      </geometry>
      <material
        name="">
        <color
          rgba="0.792156862745098 0.819607843137255 0.933333333333333 1" />
      </material>
    </visual>
    <collision>
      <origin
        xyz="0 0 0"
        rpy="0 0 0" />
      <geometry>
        <mesh
          filename="package://hrl_base_selection/urdf/wheelchair_henry/meshes/arm_left_link.STL" />
      </geometry>
    </collision>
  </link>
  <joint
    name="wheelchair/body_arm_left_joint"
    type="revolute">
    <origin
      xyz="0.09652 0 -0.17526"
      rpy="2.6872E-15 8.287E-14 0.033074" />
    <parent
      link="wheelchair/upper_body_link" />
    <child
      link="wheelchair/arm_left_link" />
    <axis
      xyz="0 0 1" />
    <limit
      lower="-3"
      upper="3"
      effort="0"
      velocity="0" />
  </joint>
  <link
    name="wheelchair/forearm_left_link">
    <visual>
      <origin
        xyz="0 0 0"
        rpy="0 0 0" />
      <geometry>
        <mesh
          filename="package://hrl_base_selection/urdf/wheelchair_henry/meshes/forearm_left_link.STL" />
      </geometry>
      <material
        name="">
        <color
          rgba="0.792156862745098 0.819607843137255 0.933333333333333 1" />
      </material>
    </visual>
    <collision>
      <origin
        xyz="0 0 0"
        rpy="0 0 0" />
      <geometry>
        <mesh
          filename="package://hrl_base_selection/urdf/wheelchair_henry/meshes/forearm_left_link.STL" />
      </geometry>
    </collision>
  </link>
  <joint
    name="wheelchair/arm_forearm_left_joint"
    type="revolute">
    <origin
      xyz="0.28174 -0.0106 -0.04953"
      rpy="1.1849E-16 -8.3419E-14 -1.6268E-27" />
    <parent
      link="wheelchair/arm_left_link" />
    <child
      link="wheelchair/forearm_left_link" />
    <axis
      xyz="0 0 1" />
    <limit
      lower="-3"
      upper="3"
      effort="0"
      velocity="0" />
  </joint>
  <link
    name="wheelchair/hand_left_link">
    <visual>
      <origin
        xyz="0 0 0"
        rpy="0 0 0" />
      <geometry>
        <mesh
          filename="package://hrl_base_selection/urdf/wheelchair_henry/meshes/hand_left_link.STL" />
      </geometry>
      <material
        name="">
        <color
          rgba="0.792156862745098 0.819607843137255 0.933333333333333 1" />
      </material>
    </visual>
    <collision>
      <origin
        xyz="0 0 0"
        rpy="0 0 0" />
      <geometry>
        <mesh
          filename="package://hrl_base_selection/urdf/wheelchair_henry/meshes/hand_left_link.STL" />
      </geometry>
    </collision>
  </link>
  <joint
    name="wheelchair/forearm_hand_left_joint"
    type="revolute">
    <origin
      xyz="0.25146 0 0"
      rpy="1.3447E-16 8.3999E-14 1.6283E-27" />
    <parent
      link="wheelchair/forearm_left_link" />
    <child
      link="wheelchair/hand_left_link" />
    <axis
      xyz="0 0 1" />
    <limit
      lower="-3"
      upper="3"
      effort="0"
      velocity="0" />
  </joint>
  <link
    name="wheelchair/arm_right_link">
    <visual>
      <origin
        xyz="0 0 0"
        rpy="0 0 0" />
      <geometry>
        <mesh
          filename="package://hrl_base_selection/urdf/wheelchair_henry/meshes/arm_right_link.STL" />
      </geometry>
      <material
        name="">
        <color
          rgba="0.792156862745098 0.819607843137255 0.933333333333333 1" />
      </material>
    </visual>
    <collision>
      <origin
        xyz="0 0 0"
        rpy="0 0 0" />
      <geometry>
        <mesh
          filename="package://hrl_base_selection/urdf/wheelchair_henry/meshes/arm_right_link.STL" />
      </geometry>
    </collision>
  </link>
  <joint
    name="wheelchair/body_arm_right_joint"
    type="revolute">
    <origin
      xyz="0.09652 0 0.17526"
      rpy="-3.0757E-16 8.2843E-14 -0.0045332" />
    <parent
      link="wheelchair/upper_body_link" />
    <child
      link="wheelchair/arm_right_link" />
    <axis
      xyz="0 0 1" />
    <limit
      lower="-3"
      upper="3"
      effort="0"
      velocity="0" />
  </joint>
  <link
    name="wheelchair/forearm_right_link">
    <visual>
      <origin
        xyz="0 0 0"
        rpy="0 0 0" />
      <geometry>
        <mesh
          filename="package://hrl_base_selection/urdf/wheelchair_henry/meshes/forearm_right_link.STL" />
      </geometry>
      <material
        name="">
        <color
          rgba="0.792156862745098 0.819607843137255 0.933333333333333 1" />
      </material>
    </visual>
    <collision>
      <origin
        xyz="0 0 0"
        rpy="0 0 0" />
      <geometry>
        <mesh
          filename="package://hrl_base_selection/urdf/wheelchair_henry/meshes/forearm_right_link.STL" />
      </geometry>
    </collision>
  </link>
  <joint
    name="wheelchair/arm_forearm_right_joint"
    type="revolute">
    <origin
      xyz="0.28194 0 0.04953"
      rpy="2.6089E-19 -8.3342E-14 0.037607" />
    <parent
      link="wheelchair/arm_right_link" />
    <child
      link="wheelchair/forearm_right_link" />
    <axis
      xyz="0 0 1" />
    <limit
      lower="-3"
      upper="3"
      effort="0"
      velocity="0" />
  </joint>
  <link
    name="wheelchair/hand_right_link">
    <visual>
      <origin
        xyz="0 0 0"
        rpy="0 0 0" />
      <geometry>
        <mesh
          filename="package://hrl_base_selection/urdf/wheelchair_henry/meshes/hand_right_link.STL" />
      </geometry>
      <material
        name="">
        <color
          rgba="0.792156862745098 0.819607843137255 0.933333333333333 1" />
      </material>
    </visual>
    <collision>
      <origin
        xyz="0 0 0"
        rpy="0 0 0" />
      <geometry>
        <mesh
          filename="package://hrl_base_selection/urdf/wheelchair_henry/meshes/hand_right_link.STL" />
      </geometry>
    </collision>
  </link>
  <joint
    name="wheelchair/forearm_hand_right_joint"
    type="revolute">
    <origin
      xyz="0.25146 0 0"
      rpy="1.9364E-14 8.3335E-14 1.6151E-27" />
    <parent
      link="wheelchair/forearm_right_link" />
    <child
      link="wheelchair/hand_right_link" />
    <axis
      xyz="0 0 1" />
    <limit
      lower="-3"
      upper="3"
      effort="0"
      velocity="0" />
  </joint>

</robot>