<robot
  name="autobed_simulation_withbody_normal">
  <link
    name="base_link">
    <inertial>
      <origin
        xyz="1.07 3.41318994679704E-16 0.0955223671928148"
        rpy="0 0 0" />
      <mass
        value="4.87911473693544" />
      <inertia
        ixx="0.908453350878167"
        ixy="-1.4432899320127E-15"
        ixz="1.44902222679625E-15"
        iyy="5.58609846231739"
        iyz="6.42783551354056E-16"
        izz="6.49455181319556" />
    </inertial>
    <visual>
      <origin
        xyz="0 0 0"
        rpy="0 0 0" />
      <geometry>
        <mesh
          filename="package://autobed_simulation_withbody_normal/meshes/base_link.STL" />
      </geometry>
      <material
        name="">
        <color
          rgba="0.792156862745098 0.819607843137255 0.933333333333333 1" />
      </material>
    </visual>
    <collision>
      <origin
        xyz="0 0 0"
        rpy="0 0 0" />
      <geometry>
        <mesh
          filename="package://autobed_simulation_withbody_normal/meshes/base_link.STL" />
      </geometry>
    </collision>
  </link>
  <link
    name="bed_frame_link">
    <inertial>
      <origin
        xyz="1.13803002623393 -9.61255541847432E-16 0.0205474290601526"
        rpy="0 0 0" />
      <mass
        value="260.628872094939" />
      <inertia
        ixx="0.457210122407708"
        ixy="-1.23643446491761E-14"
        ixz="1.09916586450599"
        iyy="3.099683546515"
        iyz="5.14308505484892E-15"
        izz="2.64247342410729" />
    </inertial>
    <visual>
      <origin
        xyz="0 0 0"
        rpy="0 0 0" />
      <geometry>
        <mesh
          filename="package://autobed_simulation_withbody_normal/meshes/bed_frame_link.STL" />
      </geometry>
      <material
        name="">
        <color
          rgba="0.792156862745098 0.819607843137255 0.933333333333333 1" />
      </material>
    </visual>
    <collision>
      <origin
        xyz="0 0 0"
        rpy="0 0 0" />
      <geometry>
        <mesh
          filename="package://autobed_simulation_withbody_normal/meshes/bed_frame_link.STL" />
      </geometry>
    </collision>
  </link>
  <joint
    name="tele_legs_joint"
    type="prismatic">
    <origin
      xyz="-0.0400000000000005 0 0.320000000000001"
      rpy="0 0 0" />
    <parent
      link="base_link" />
    <child
      link="bed_frame_link" />
    <axis
      xyz="0 1 0" />
  </joint>
  <link
    name="leg_rest_upper">
    <inertial>
      <origin
        xyz="0.185000000000001 0.104999999999997 -7.98241372751238E-16"
        rpy="0 0 0" />
      <mass
        value="67.9875000000001" />
      <inertia
        ixx="0"
        ixy="0"
        ixz="0"
        iyy="0"
        iyz="0"
        izz="0" />
    </inertial>
    <visual>
      <origin
        xyz="0 0 0"
        rpy="0 0 0" />
      <geometry>
        <mesh
          filename="package://autobed_simulation_withbody_normal/meshes/leg_rest_upper.STL" />
      </geometry>
      <material
        name="">
        <color
          rgba="0.792156862745098 0.819607843137255 0.933333333333333 1" />
      </material>
    </visual>
    <collision>
      <origin
        xyz="0 0 0"
        rpy="0 0 0" />
      <geometry>
        <mesh
          filename="package://autobed_simulation_withbody_normal/meshes/leg_rest_upper.STL" />
      </geometry>
    </collision>
  </link>
  <joint
    name="leg_rest_upper_hinge"
    type="revolute">
    <origin
      xyz="1.075 0 0"
      rpy="1.5707963267949 -1.84377299293392E-16 7.65430446472183E-16" />
    <parent
      link="bed_frame_link" />
    <child
      link="leg_rest_upper" />
    <axis
      xyz="0 0 -1" />
  </joint>
  <link
    name="leg_rest_lower">
    <inertial>
      <origin
        xyz="0.325 0.105 -3.00111945743508E-16"
        rpy="0 0 0" />
      <mass
        value="119.4375" />
      <inertia
        ixx="0"
        ixy="0"
        ixz="0"
        iyy="0"
        iyz="0"
        izz="0" />
    </inertial>
    <visual>
      <origin
        xyz="0 0 0"
        rpy="0 0 0" />
      <geometry>
        <mesh
          filename="package://autobed_simulation_withbody_normal/meshes/leg_rest_lower.STL" />
      </geometry>
      <material
        name="">
        <color
          rgba="0.792156862745098 0.819607843137255 0.933333333333333 1" />
      </material>
    </visual>
    <collision>
      <origin
        xyz="0 0 0"
        rpy="0 0 0" />
      <geometry>
        <mesh
          filename="package://autobed_simulation_withbody_normal/meshes/leg_rest_lower.STL" />
      </geometry>
    </collision>
  </link>
  <joint
    name="leg_rest_lower_hinge"
    type="revolute">
    <origin
      xyz="0.370000000000001 0 0"
      rpy="8.46545056276682E-16 -2.4743657509036E-16 -1.8315782125782E-16" />
    <parent
      link="leg_rest_upper" />
    <child
      link="leg_rest_lower" />
    <axis
      xyz="0 0 -1" />
  </joint>
  <link
    name="head_rest_link">
    <inertial>
      <origin
        xyz="0.347706610619294 0.119461080972176 7.18320301571672E-17"
        rpy="0 0 0" />
      <mass
        value="140.777224765126" />
      <inertia
        ixx="0"
        ixy="0"
        ixz="0"
        iyy="0"
        iyz="0"
        izz="0" />
    </inertial>
    <visual>
      <origin
        xyz="0 0 0"
        rpy="0 0 0" />
      <geometry>
        <mesh
          filename="package://autobed_simulation_withbody_normal/meshes/head_rest_link.STL" />
      </geometry>
      <material
        name="">
        <color
          rgba="0.792156862745098 0.819607843137255 0.933333333333333 1" />
      </material>
    </visual>
    <collision>
      <origin
        xyz="0 0 0"
        rpy="0 0 0" />
      <geometry>
        <mesh
          filename="package://autobed_simulation_withbody_normal/meshes/head_rest_link.STL" />
      </geometry>
    </collision>
  </link>
  <joint
    name="head_rest_hinge"
    type="revolute">
    <origin
      xyz="0.795 0 0"
      rpy="1.5707963267949 2.84158644671567E-16 -3.14159265358979" />
    <parent
      link="bed_frame_link" />
    <child
      link="head_rest_link" />
    <axis
      xyz="0 0 1" />
  </joint>
  <link
    name="wall_link">
    <inertial>
      <origin
        xyz="-0.743896617818673 0.0269530666641218 0.648196106542823"
        rpy="0 0 0" />
      <mass
        value="74.9999999999973" />
      <inertia
        ixx="0"
        ixy="0"
        ixz="0"
        iyy="0"
        iyz="0"
        izz="0" />
    </inertial>
    <visual>
      <origin
        xyz="0 0 0"
        rpy="0 0 0" />
      <geometry>
        <mesh
          filename="package://autobed_simulation_withbody_normal/meshes/wall_link.STL" />
      </geometry>
      <material
        name="">
        <color
          rgba="0.792156862745098 0.819607843137255 0.933333333333333 1" />
      </material>
    </visual>
    <collision>
      <origin
        xyz="0 0 0"
        rpy="0 0 0" />
      <geometry>
        <mesh
          filename="package://autobed_simulation_withbody_normal/meshes/wall_link.STL" />
      </geometry>
    </collision>
  </link>
  <joint
    name="origin_wall_joint"
    type="prismatic">
    <origin
      xyz="0.610627419320058 -0.155260000000016 0.574890377092541"
      rpy="-0.00650994084197508 0.0370393769946504 -0.174021765425405" />
    <parent
      link="base_link" />
    <child
      link="wall_link" />
    <axis
      xyz="0.984220866265583 0.172903665695305 0.0375979892620764" />
  </joint>
</robot>