<?xml version="1.0"?>
<robot
  name="bed_and_environment_henry_tray">
  <link
   name="autobed/base_link">
    <inertial>
      <origin
        xyz="1.07 3.94840580504828E-16 0.0837923121940762"
        rpy="0 0 0" />
      <mass
        value="6.1860172808288" />
      <inertia
        ixx="1.21978721906848"
        ixy="2.22044604925031E-15"
        ixz="-1.78284289885571E-15"
        iyy="7.15036992783298"
        iyz="-7.76907347784197E-16"
        izz="8.24641740321532" />
    </inertial>
    <visual>
      <origin
        xyz="0 0 0"
        rpy="0 0 0" />
      <geometry>
        <mesh
          filename="package://hrl_base_selection/urdf/bed_and_environment_henry_tray/meshes/base_link.STL" />
      </geometry>
    </visual>
    <collision>
      <origin
        xyz="0 0 0"
        rpy="0 0 0" />
      <geometry>
        <mesh
          filename="package://hrl_base_selection/urdf/bed_and_environment_henry_tray/meshes/base_link.STL" />
      </geometry>
    </collision>
  </link>
    <link
   name="autobed/wall_link">
    <inertial>
      <origin
        xyz="1.85973617610096 0.322876413955559 0.506156564666783"
        rpy="0 0 0" />
      <mass
        value="3480.34879229199" />
      <inertia
        ixx="6193.4907032472"
        ixy="3253.06972401852"
        ixz="-11.5632809249146"
        iyy="7114.12294656335"
        iyz="386.100445501856"
        izz="12101.3286461396" />
    </inertial>
    <visual>
      <origin
        xyz="0 0 0"
        rpy="0 0 0" />
      <geometry>
        <mesh
          filename="package://hrl_base_selection/urdf/bed_and_environment_henry_tray/meshes/wall_link.STL" />
      </geometry>
    </visual>
    <collision>
      <origin
        xyz="0 0 0"
        rpy="0 0 0" />
      <geometry>
        <mesh
          filename="package://hrl_base_selection/urdf/bed_and_environment_henry_tray/meshes/wall_link.STL" />
      </geometry>
    </collision>
  </link>
  <joint
   name="autobed/origin_wall_joint"
    type="fixed">
    <origin
      xyz="-0.12155 -0.0043316 0"
      rpy="0 0 -0.053897" />
    <parent
      link="autobed/base_link" />
    <child
      link="autobed/wall_link" />
    <axis
      xyz="0 0 0" />
  </joint>
  <link
   name="autobed/bed_frame_link">
    <inertial>
      <origin
        xyz="1.20574977089702 -0.00197319632794563 0.010463658046454"
        rpy="0 0 0" />
      <mass
        value="298.525793737685" />
      <inertia
        ixx="25.3079805393988"
        ixy="0.124705215046845"
        ixz="-6.18752707469867"
        iyy="161.196265779885"
        iyz="0.0978345240222597"
        izz="178.196491872743" />
    </inertial>
    <visual>
      <origin
        xyz="0 0 0"
        rpy="0 0 0" />
      <geometry>
        <mesh
          filename="package://hrl_base_selection/urdf/bed_and_environment_henry_tray/meshes/bed_frame_link.STL" />
      </geometry>
    </visual>
    <collision>
      <origin
        xyz="0 0 0"
        rpy="0 0 0" />
      <geometry>
        <mesh
          filename="package://hrl_base_selection/urdf/bed_and_environment_henry_tray/meshes/bed_frame_link.STL" />
      </geometry>
    </collision>
  </link>
  <joint
   name="autobed/tele_legs_joint"
    type="prismatic">
    <origin
      xyz="-0.0400000000000005 0 0.320000000000001"
      rpy="0 0 0" />
    <parent
      link="autobed/base_link" />
    <child
      link="autobed/bed_frame_link" />
    <axis
      xyz="0 0 1" />
    <limit
      lower="-1"
      upper="1"
      effort="0"
      velocity="0" />
  </joint>
  <link
   name="autobed/leg_rest_upper">
    <inertial>
      <origin
        xyz="0.184999999999998 0.10500000000001 6.79804630482359E-16"
        rpy="0 0 0" />
      <mass
        value="71.0955000000001" />
      <inertia
        ixx="5.22152012812501"
        ixy="-3.21389401302034E-17"
        ixz="-3.22023131917487E-17"
        iyy="5.77132532812501"
        iyz="-2.87322532068486E-15"
        izz="1.072357125" />
    </inertial>
    <visual>
      <origin
        xyz="0 0 0"
        rpy="0 0 0" />
      <geometry>
        <mesh
          filename="package://hrl_base_selection/urdf/bed_and_environment_henry_tray/meshes/leg_rest_upper.STL" />
      </geometry>
    </visual>
    <collision>
      <origin
        xyz="0 0 0"
        rpy="0 0 0" />
      <geometry>
        <mesh
          filename="package://hrl_base_selection/urdf/bed_and_environment_henry_tray/meshes/leg_rest_upper.STL" />
      </geometry>
    </collision>
  </link>
  <joint
   name="autobed/leg_rest_upper_hinge"
    type="revolute">
    <origin
      xyz="1.075 0 0"
      rpy="1.5708 -1.8438E-16 7.6543E-16" />
    <parent
      link="autobed/bed_frame_link" />
    <child
      link="autobed/leg_rest_upper" />
    <axis
      xyz="0 0 1" />
    <limit
      lower="-2"
      upper="2"
      effort="0"
      velocity="0" />
  </joint>
  <link
   name="autobed/leg_rest_lower">
    <inertial>
      <origin
        xyz="0.325000000000004 0.104999999999987 -1.38760699713425E-16"
        rpy="0 0 0" />
      <mass
        value="124.8975" />
      <inertia
        ixx="9.172940765625"
        ixy="-4.25925024767052E-17"
        ixz="-8.25969319809873E-16"
        iyy="13.111375265625"
        iyz="2.10674154540826E-16"
        izz="4.856431125" />
    </inertial>
    <visual>
      <origin
        xyz="0 0 0"
        rpy="0 0 0" />
      <geometry>
        <mesh
          filename="package://hrl_base_selection/urdf/bed_and_environment_henry_tray/meshes/leg_rest_lower.STL" />
      </geometry>
    </visual>
    <collision>
      <origin
        xyz="0 0 0"
        rpy="0 0 0" />
      <geometry>
        <mesh
          filename="package://hrl_base_selection/urdf/bed_and_environment_henry_tray/meshes/leg_rest_lower.STL" />
      </geometry>
    </collision>
  </link>
  <joint
   name="autobed/leg_rest_lower_hinge"
    type="revolute">
    <origin
      xyz="0.37 0 0"
      rpy="8.4655E-16 -2.4744E-16 -1.8316E-16" />
    <parent
      link="autobed/leg_rest_upper" />
    <child
      link="autobed/leg_rest_lower" />
    <axis
      xyz="0 0 -1" />
    <limit
      lower="-2"
      upper="2"
      effort="0"
      velocity="0" />
  </joint>
  <link
   name="autobed/head_rest_link">
    <inertial>
      <origin
        xyz="0.338540021639504 -0.102807900235519 0.0331726512276706"
        rpy="0 0 0" />
      <mass
        value="158.265573279578" />
      <inertia
        ixx="13.8116841883572"
        ixy="0.366851813056848"
        ixz="-0.640983438566653"
        iyy="18.5647228773414"
        iyz="-0.857921499431992"
        izz="7.19318513198363" />
    </inertial>
    <visual>
      <origin
        xyz="0 0 0"
        rpy="0 0 0" />
      <geometry>
        <mesh
          filename="package://hrl_base_selection/urdf/bed_and_environment_henry_tray/meshes/head_rest_link.STL" />
      </geometry>
    </visual>
    <collision>
      <origin
        xyz="0 0 0"
        rpy="0 0 0" />
      <geometry>
        <mesh
          filename="package://hrl_base_selection/urdf/bed_and_environment_henry_tray/meshes/head_rest_link.STL" />
      </geometry>
    </collision>
  </link>
  <joint
   name="autobed/head_rest_hinge"
    type="revolute">
    <origin
      xyz="0.795 0 0.21"
      rpy="1.5708 0 -3.1416" />
    <parent
      link="autobed/bed_frame_link" />
    <child
      link="autobed/head_rest_link" />
    <axis
      xyz="0 0 1" />
    <limit
      lower="-2"
      upper="2"
      effort="0"
      velocity="0" />
  </joint>
  <link
    name="autobed/neck_rotated_to_worldframe_link">
  </link>
  <joint
    name="autobed/headrest_bed_to_worldframe_joint"
    type="revolute">
    <origin
      xyz="0.25949 0.1 0"
      rpy="0. 0. 0." />
    <!--<origin-->
      <!--xyz="0.40949 0.05 0"-->
      <!--rpy="0. 0. 0." />-->
    <parent
      link="autobed/head_rest_link" />
    <child
      link="autobed/neck_rotated_to_worldframe_link" />
    <axis
      xyz="0 0 1" />
    <limit
      lower="-2"
      upper="2"
      effort="0"
      velocity="0" />
  </joint>
  <link
    name="autobed/neck_updown_worldframe_translation_link">
  </link>
  <joint
    name="autobed/bed_neck_worldframe_updown_joint"
    type="prismatic">
    <origin
      xyz="0.0 0.0 0"
      rpy="0.0 0.0 0.0" />
    <parent
      link="autobed/neck_rotated_to_worldframe_link" />
    <child
      link="autobed/neck_updown_worldframe_translation_link" />
    <axis
      xyz="-1 0 0" />
    <limit
      lower="-2"
      upper="2"
      effort="0"
      velocity="0" />
  </joint>
  <link
    name="autobed/neck_rotated_to_bedframe_link">
  </link>
  <joint
    name="autobed/bed_neck_to_bedframe_joint"
    type="revolute">
    <origin
      xyz="0.0 0.0 0"
      rpy="0. 0. 0." />
    <parent
      link="autobed/neck_updown_worldframe_translation_link" />
    <child
      link="autobed/neck_rotated_to_bedframe_link" />
    <axis
      xyz="0 0 1" />
    <limit
      lower="-2"
      upper="2"
      effort="0"
      velocity="0" />
  </joint>
  <link
    name="autobed/neck_updown_bedframe_translation_link">
  </link>
  <joint
    name="autobed/bed_neck_base_updown_bedframe_joint"
    type="prismatic">
    <origin
      xyz="0.0 0.0 0"
      rpy="0. 0. 0." />
    <parent
      link="autobed/neck_rotated_to_bedframe_link" />
    <child
      link="autobed/neck_updown_bedframe_translation_link" />
    <axis
      xyz="-1 0 0" />
    <limit
      lower="-2"
      upper="2"
      effort="0"
      velocity="0" />
  </joint>
  <link
    name="autobed/neck_base_link">
  </link>
  <joint
    name="autobed/bed_neck_base_leftright_joint"
    type="prismatic">
    <origin
      xyz="0 0 0"
      rpy="0 3.14159 0" />
    <parent
      link="autobed/neck_updown_bedframe_translation_link" />
    <child
      link="autobed/neck_base_link" />
    <axis
      xyz="0 0 -1" />
    <limit
      lower="-2"
      upper="2"
      effort="0"
      velocity="0" />
  </joint>
  <link
    name="autobed/neck_twist_link">
  </link>
  <joint
    name="autobed/neck_twist_joint"
    type="revolute">
    <origin
      xyz="0.0 0.0 0"
      rpy="0. 0. 0." />
    <parent
      link="autobed/neck_base_link" />
    <child
      link="autobed/neck_twist_link" />
    <axis
      xyz="1 0 0" />
    <limit
      lower="-2"
      upper="2"
      effort="0"
      velocity="0" />
  </joint>
  <link
    name="autobed/neck_tilt_link">
  </link>
  <joint
    name="autobed/neck_tilt_joint"
    type="revolute">
    <origin
      xyz="0.0 0.0 0"
      rpy="0. 0. 0." />
    <parent
      link="autobed/neck_twist_link" />
    <child
      link="autobed/neck_tilt_link" />
    <axis
      xyz="0 0 -1" />
    <limit
      lower="-2"
      upper="2"
      effort="0"
      velocity="0" />
  </joint>
  <link
    name="autobed/neck_link">
    <visual>
      <origin
        xyz="0 0 0"
        rpy="0 0 0" />
      <geometry>
        <mesh
          filename="package://hrl_base_selection/urdf/bed_and_environment_henry_tray/meshes/neck_link.STL" />
      </geometry>
      <material
        name="">
        <color
          rgba="0.792156862745098 0.819607843137255 0.933333333333333 1" />
      </material>
    </visual>
    <collision>
      <origin
        xyz="0 0 0"
        rpy="0 0 0" />
      <geometry>
        <mesh
          filename="package://hrl_base_selection/urdf/bed_and_environment_henry_tray/meshes/neck_link.STL" />
      </geometry>
    </collision>
  </link>
  <joint
    name="autobed/neck_to_neck_top_joint"
    type="fixed">
    <origin
      xyz="-0.07239 0 0"
      rpy="0 0 0" />
    <parent
      link="autobed/neck_tilt_link" />
    <child
      link="autobed/neck_link" />
  </joint>
  <link
    name="autobed/neck_top_rotated_link">
  </link>
  <joint
    name="autobed/neck_rotation_fixed_joint"
    type="fixed">
    <origin
      xyz="0 0 0"
      rpy="-1.570796 0 1.570796" />
    <parent
      link="autobed/neck_link" />
    <child
      link="autobed/neck_top_rotated_link" />
    <axis
      xyz="0 0 1" />
    <limit
      lower="-2"
      upper="2"
      effort="0"
      velocity="0" />
  </joint>
  <link
    name="autobed/head_roty_link">
  </link>
  <joint
    name="autobed/neck_head_roty_joint"
    type="revolute">
    <origin
      xyz="0.0154 0 0.07779"
      rpy="0 0 0" />
    <parent
      link="autobed/neck_top_rotated_link" />
    <child
      link="autobed/head_roty_link" />
    <axis
      xyz="0 1 0" />
    <limit
      lower="-2"
      upper="2"
      effort="0"
      velocity="0" />
  </joint>
  <link
    name="autobed/head_rotz_link">
  </link>
  <joint
    name="autobed/neck_head_rotz_joint"
    type="revolute">
    <origin
      xyz="0 0 0"
      rpy="0 0 0" />
    <parent
      link="autobed/head_roty_link" />
    <child
      link="autobed/head_rotz_link" />
    <axis
      xyz="0 0 1" />
    <limit
      lower="-2"
      upper="2"
      effort="0"
      velocity="0" />
  </joint>

  <link
    name="autobed/head_link">
    <visual>
      <origin
        xyz="0 0 0"
        rpy="0 0 0" />
      <geometry>
        <mesh
          filename="package://hrl_base_selection/urdf/bed_and_environment_henry_tray/meshes/head_link.STL" />
      </geometry>
      <material
        name="">
        <color
          rgba="0.792156862745098 0.819607843137255 0.933333333333333 1" />
      </material>
    </visual>
    <collision>
      <origin
        xyz="0 0 0"
        rpy="0 0 0" />
      <geometry>
        <mesh
          filename="package://hrl_base_selection/urdf/bed_and_environment_henry_tray/meshes/head_link.STL" />
      </geometry>
    </collision>
  </link>
  <joint
    name="autobed/neck_head_rotx_joint"
    type="revolute">
    <origin
      xyz="0 0 0"
      rpy="0 0 0" />
    <parent
      link="autobed/head_rotz_link" />
    <child
      link="autobed/head_link" />
    <axis
      xyz="1 0 0" />
    <limit
      lower="-2"
      upper="2"
      effort="0"
      velocity="0" />
  </joint>
  <link
    name="autobed/upper_body_link">
    <visual>
      <origin
        xyz="0 0 0"
        rpy="0 0 0" />
      <geometry>
        <mesh
          filename="package://hrl_base_selection/urdf/bed_and_environment_henry_tray/meshes/upper_body_link.STL" />
      </geometry>
      <material
        name="">
        <color
          rgba="0.792156862745098 0.819607843137255 0.933333333333333 1" />
      </material>
    </visual>
    <collision>
      <origin
        xyz="0 0 0"
        rpy="0 0 0" />
      <geometry>
        <mesh
          filename="package://hrl_base_selection/urdf/bed_and_environment_henry_tray/meshes/upper_body_link.STL" />
      </geometry>
    </collision>
  </link>
  <joint
    name="autobed/neck_body_joint"
    type="revolute">
    <origin
      xyz="0.00 0 0"
      rpy="0 0 0" />
    <parent
      link="autobed/neck_base_link" />
    <child
      link="autobed/upper_body_link" />
    <axis
      xyz="0 0 -1" />
    <limit
      lower="-2"
      upper="2"
      effort="0"
      velocity="0" />
  </joint>
  <link
    name="autobed/mid_body_link">
    <visual>
      <origin
        xyz="0 0 0"
        rpy="0 0 0" />
      <geometry>
        <mesh
          filename="package://hrl_base_selection/urdf/bed_and_environment_henry_tray/meshes/mid_body_link.STL" />
      </geometry>
      <material
        name="">
        <color
          rgba="0.792156862745098 0.819607843137255 0.933333333333333 1" />
      </material>
    </visual>
    <collision>
      <origin
        xyz="0 0 0"
        rpy="0 0 0" />
      <geometry>
        <mesh
          filename="package://hrl_base_selection/urdf/bed_and_environment_henry_tray/meshes/mid_body_link.STL" />
      </geometry>
    </collision>
  </link>
  <joint
    name="autobed/upper_mid_body_joint"
    type="revolute">
    <origin
      xyz="0.35052 0 0"
      rpy="0 0 0" />
    <parent
      link="autobed/upper_body_link" />
    <child
      link="autobed/mid_body_link" />
    <axis
      xyz="0 0 1" />
    <limit
      lower="-2"
      upper="2"
      effort="0"
      velocity="0" />
  </joint>
  <link
    name="autobed/lower_body_link">
    <visual>
      <origin
        xyz="0 0 0"
        rpy="0 0 0" />
      <geometry>
        <mesh
          filename="package://hrl_base_selection/urdf/bed_and_environment_henry_tray/meshes/lower_body_link.STL" />
      </geometry>
      <material
        name="">
        <color
          rgba="0.792156862745098 0.819607843137255 0.933333333333333 1" />
      </material>
    </visual>
    <collision>
      <origin
        xyz="0 0 0"
        rpy="0 0 0" />
      <geometry>
        <mesh
          filename="package://hrl_base_selection/urdf/bed_and_environment_henry_tray/meshes/lower_body_link.STL" />
      </geometry>
    </collision>
  </link>
  <joint
    name="autobed/mid_lower_body_joint"
    type="revolute">
    <origin
      xyz="0.15113 0 0"
      rpy="0 0 0" />
    <parent
      link="autobed/mid_body_link" />
    <child
      link="autobed/lower_body_link" />
    <axis
      xyz="0 0 1" />
    <limit
      lower="-2"
      upper="2"
      effort="0"
      velocity="0" />
  </joint>
  <link
    name="autobed/quad_left_link">
    <visual>
      <origin
        xyz="0 0 0"
        rpy="0 0 0" />
      <geometry>
        <mesh
          filename="package://hrl_base_selection/urdf/bed_and_environment_henry_tray/meshes/quad_left_link.STL" />
      </geometry>
      <material
        name="">
        <color
          rgba="0.792156862745098 0.819607843137255 0.933333333333333 1" />
      </material>
    </visual>
    <collision>
      <origin
        xyz="0 0 0"
        rpy="0 0 0" />
      <geometry>
        <mesh
          filename="package://hrl_base_selection/urdf/bed_and_environment_henry_tray/meshes/quad_left_link.STL" />
      </geometry>
    </collision>
  </link>
  <joint
    name="autobed/body_quad_left_joint"
    type="revolute">
    <origin
      xyz="0.05207 0 -0.08636"
      rpy="0 0 -.25" />
    <parent
      link="autobed/lower_body_link" />
    <child
      link="autobed/quad_left_link" />
    <axis
      xyz="0 0 1" />
    <limit
      lower="-3."
      upper="3."
      effort="0"
      velocity="0" />
  </joint>
  <link
    name="autobed/calf_left_link">
    <visual>
      <origin
        xyz="0 0 0"
        rpy="0 0 0" />
      <geometry>
        <mesh
          filename="package://hrl_base_selection/urdf/bed_and_environment_henry_tray/meshes/calf_left_link.STL" />
      </geometry>
      <material
        name="">
        <color
          rgba="0.792156862745098 0.819607843137255 0.933333333333333 1" />
      </material>
    </visual>
    <collision>
      <origin
        xyz="0 0 0"
        rpy="0 0 0" />
      <geometry>
        <mesh
          filename="package://hrl_base_selection/urdf/bed_and_environment_henry_tray/meshes/calf_left_link.STL" />
      </geometry>
    </collision>
  </link>
  <joint
    name="autobed/quad_calf_left_joint"
    type="revolute">
    <origin
      xyz="0.41218 0.11044 0"
      rpy="3.14159 0 3.43" />
    <parent
      link="autobed/quad_left_link" />
    <child
      link="autobed/calf_left_link" />
    <axis
      xyz="0 0 1" />
    <limit
      lower="-3."
      upper="3."
      effort="0"
      velocity="0" />
  </joint>
  <link
    name="autobed/foot_left_link">
    <visual>
      <origin
        xyz="0 0 0"
        rpy="0 0 0" />
      <geometry>
        <mesh
          filename="package://hrl_base_selection/urdf/bed_and_environment_henry_tray/meshes/foot_left_link.STL" />
      </geometry>
      <material
        name="">
        <color
          rgba="0.792156862745098 0.819607843137255 0.933333333333333 1" />
      </material>
    </visual>
    <collision>
      <origin
        xyz="0 0 0"
        rpy="0 0 0" />
      <geometry>
        <mesh
          filename="package://hrl_base_selection/urdf/bed_and_environment_henry_tray/meshes/foot_left_link.STL" />
      </geometry>
    </collision>
  </link>
  <joint
    name="autobed/calf_foot_left_joint"
    type="revolute">
    <origin
      xyz="-0.41279 -0.03188 0"
      rpy="0 0 0.09" />
    <parent
      link="autobed/calf_left_link" />
    <child
      link="autobed/foot_left_link" />
    <axis
      xyz="0 0 1" />
    <limit
      lower="-3."
      upper="3."
      effort="0"
      velocity="0" />
  </joint>
  <link
    name="autobed/quad_right_link">
    <visual>
      <origin
        xyz="0 0 0"
        rpy="0 0 0" />
      <geometry>
        <mesh
          filename="package://hrl_base_selection/urdf/bed_and_environment_henry_tray/meshes/quad_right_link.STL" />
      </geometry>
      <material
        name="">
        <color
          rgba="0.792156862745098 0.819607843137255 0.933333333333333 1" />
      </material>
    </visual>
    <collision>
      <origin
        xyz="0 0 0"
        rpy="0 0 0" />
      <geometry>
        <mesh
          filename="package://hrl_base_selection/urdf/bed_and_environment_henry_tray/meshes/quad_right_link.STL" />
      </geometry>
    </collision>
  </link>
  <joint
    name="autobed/body_quad_right_joint"
    type="revolute">
    <origin
      xyz="0.05207 0 0.08636"
      rpy="0 0 -.25" />
    <parent
      link="autobed/lower_body_link" />
    <child
      link="autobed/quad_right_link" />
    <axis
      xyz="0 0 1" />
    <limit
      lower="-3"
      upper="3"
      effort="0"
      velocity="0" />
  </joint>
  <link
    name="autobed/calf_right_link">
    <visual>
      <origin
        xyz="0 0 0"
        rpy="0 0 0" />
      <geometry>
        <mesh
          filename="package://hrl_base_selection/urdf/bed_and_environment_henry_tray/meshes/calf_right_link.STL" />
      </geometry>
      <material
        name="">
        <color
          rgba="0.792156862745098 0.819607843137255 0.933333333333333 1" />
      </material>
    </visual>
    <collision>
      <origin
        xyz="0 0 0"
        rpy="0 0 0" />
      <geometry>
        <mesh
          filename="package://hrl_base_selection/urdf/bed_and_environment_henry_tray/meshes/calf_right_link.STL" />
      </geometry>
    </collision>
  </link>
  <joint
    name="autobed/quad_calf_right_joint"
    type="revolute">
    <origin
      xyz="0.41218 0.11044 0"
      rpy="3.14159 0 3.43" />
    <parent
      link="autobed/quad_right_link" />
    <child
      link="autobed/calf_right_link" />
    <axis
      xyz="0 0 1" />
    <limit
      lower="-3"
      upper="3"
      effort="0"
      velocity="0" />
  </joint>
  <link
    name="autobed/foot_right_link">
    <visual>
      <origin
        xyz="0 0 0"
        rpy="0 0 0" />
      <geometry>
        <mesh
          filename="package://hrl_base_selection/urdf/bed_and_environment_henry_tray/meshes/foot_right_link.STL" />
      </geometry>
      <material
        name="">
        <color
          rgba="0.792156862745098 0.819607843137255 0.933333333333333 1" />
      </material>
    </visual>
    <collision>
      <origin
        xyz="0 0 0"
        rpy="0 0 0" />
      <geometry>
        <mesh
          filename="package://hrl_base_selection/urdf/bed_and_environment_henry_tray/meshes/foot_right_link.STL" />
      </geometry>
    </collision>
  </link>
  <joint
    name="autobed/calf_foot_right_joint"
    type="revolute">
    <origin
      xyz="-0.41279 -0.03188 0"
      rpy="0 0 0.09" />
    <parent
      link="autobed/calf_right_link" />
    <child
      link="autobed/foot_right_link" />
    <axis
      xyz="0 0 1" />
    <limit
      lower="-3"
      upper="3"
      effort="0"
      velocity="0" />
  </joint>
  <link
    name="autobed/arm_left_link">
    <visual>
      <origin
        xyz="0 0 0"
        rpy="0 0 0" />
      <geometry>
        <mesh
          filename="package://hrl_base_selection/urdf/bed_and_environment_henry_tray/meshes/arm_left_link.STL" />
      </geometry>
      <material
        name="">
        <color
          rgba="0.792156862745098 0.819607843137255 0.933333333333333 1" />
      </material>
    </visual>
    <collision>
      <origin
        xyz="0 0 0"
        rpy="0 0 0" />
      <geometry>
        <mesh
          filename="package://hrl_base_selection/urdf/bed_and_environment_henry_tray/meshes/arm_left_link.STL" />
      </geometry>
    </collision>
  </link>
  <joint
    name="autobed/body_arm_left_joint"
    type="revolute">
    <origin
      xyz="0.09652 0 -0.17526"
      rpy="0 0 0" />
    <parent
      link="autobed/upper_body_link" />
    <child
      link="autobed/arm_left_link" />
    <axis
      xyz="0 0 1" />
    <limit
      lower="-3"
      upper="3"
      effort="0"
      velocity="0" />
  </joint>
  <link
    name="autobed/forearm_left_link">
    <visual>
      <origin
        xyz="0 0 0"
        rpy="0 0 0" />
      <geometry>
        <mesh
          filename="package://hrl_base_selection/urdf/bed_and_environment_henry_tray/meshes/forearm_left_link.STL" />
      </geometry>
      <material
        name="">
        <color
          rgba="0.792156862745098 0.819607843137255 0.933333333333333 1" />
      </material>
    </visual>
    <collision>
      <origin
        xyz="0 0 0"
        rpy="0 0 0" />
      <geometry>
        <mesh
          filename="package://hrl_base_selection/urdf/bed_and_environment_henry_tray/meshes/forearm_left_link.STL" />
      </geometry>
    </collision>
  </link>
  <joint
    name="autobed/arm_forearm_left_joint"
    type="revolute">
    <origin
      xyz="0.28174 -0.0106 -0.04953"
      rpy="0 0 0" />
    <parent
      link="autobed/arm_left_link" />
    <child
      link="autobed/forearm_left_link" />
    <axis
      xyz="0 0 1" />
    <limit
      lower="-3"
      upper="3"
      effort="0"
      velocity="0" />
  </joint>
  <link
    name="autobed/hand_left_link">
    <visual>
      <origin
        xyz="0 0 0"
        rpy="0 0 0" />
      <geometry>
        <mesh
          filename="package://hrl_base_selection/urdf/bed_and_environment_henry_tray/meshes/hand_left_link.STL" />
      </geometry>
      <material
        name="">
        <color
          rgba="0.792156862745098 0.819607843137255 0.933333333333333 1" />
      </material>
    </visual>
    <collision>
      <origin
        xyz="0 0 0"
        rpy="0 0 0" />
      <geometry>
        <mesh
          filename="package://hrl_base_selection/urdf/bed_and_environment_henry_tray/meshes/hand_left_link.STL" />
      </geometry>
    </collision>
  </link>
  <joint
    name="autobed/forearm_hand_left_joint"
    type="revolute">
    <origin
      xyz="0.25146 0 0"
      rpy="0 0 0" />
    <parent
      link="autobed/forearm_left_link" />
    <child
      link="autobed/hand_left_link" />
    <axis
      xyz="0 0 1" />
    <limit
      lower="-3"
      upper="3"
      effort="0"
      velocity="0" />
  </joint>
  <link
    name="autobed/arm_right_link">
    <visual>
      <origin
        xyz="0 0 0"
        rpy="0 0 0" />
      <geometry>
        <mesh
          filename="package://hrl_base_selection/urdf/bed_and_environment_henry_tray/meshes/arm_right_link.STL" />
      </geometry>
      <material
        name="">
        <color
          rgba="0.792156862745098 0.819607843137255 0.933333333333333 1" />
      </material>
    </visual>
    <collision>
      <origin
        xyz="0 0 0"
        rpy="0 0 0" />
      <geometry>
        <mesh
          filename="package://hrl_base_selection/urdf/bed_and_environment_henry_tray/meshes/arm_right_link.STL" />
      </geometry>
    </collision>
  </link>
  <joint
    name="autobed/body_arm_right_joint"
    type="revolute">
    <origin
      xyz="0.09652 0 0.17526"
      rpy="0 0 0" />
    <parent
      link="autobed/upper_body_link" />
    <child
      link="autobed/arm_right_link" />
    <axis
      xyz="0 0 1" />
    <limit
      lower="-3"
      upper="3"
      effort="0"
      velocity="0" />
  </joint>
  <link
    name="autobed/forearm_right_link">
    <visual>
      <origin
        xyz="0 0 0"
        rpy="0 0 0" />
      <geometry>
        <mesh
          filename="package://hrl_base_selection/urdf/bed_and_environment_henry_tray/meshes/forearm_right_link.STL" />
      </geometry>
      <material
        name="">
        <color
          rgba="0.792156862745098 0.819607843137255 0.933333333333333 1" />
      </material>
    </visual>
    <collision>
      <origin
        xyz="0 0 0"
        rpy="0 0 0" />
      <geometry>
        <mesh
          filename="package://hrl_base_selection/urdf/bed_and_environment_henry_tray/meshes/forearm_right_link.STL" />
      </geometry>
    </collision>
  </link>
  <joint
    name="autobed/arm_forearm_right_joint"
    type="revolute">
    <origin
      xyz="0.28194 0 0.04953"
      rpy="0 0 0" />
    <parent
      link="autobed/arm_right_link" />
    <child
      link="autobed/forearm_right_link" />
    <axis
      xyz="0 0 1" />
    <limit
      lower="-3"
      upper="3"
      effort="0"
      velocity="0" />
  </joint>
  <link
    name="autobed/hand_right_link">
    <visual>
      <origin
        xyz="0 0 0"
        rpy="0 0 0" />
      <geometry>
        <mesh
          filename="package://hrl_base_selection/urdf/bed_and_environment_henry_tray/meshes/hand_right_link.STL" />
      </geometry>
      <material
        name="">
        <color
          rgba="0.792156862745098 0.819607843137255 0.933333333333333 1" />
      </material>
    </visual>
    <collision>
      <origin
        xyz="0 0 0"
        rpy="0 0 0" />
      <geometry>
        <mesh
          filename="package://hrl_base_selection/urdf/bed_and_environment_henry_tray/meshes/hand_right_link.STL" />
      </geometry>
    </collision>
  </link>
  <joint
    name="autobed/forearm_hand_right_joint"
    type="revolute">
    <origin
      xyz="0.25146 0 0"
      rpy="0 0 0" />
    <parent
      link="autobed/forearm_right_link" />
    <child
      link="autobed/hand_right_link" />
    <axis
      xyz="0 0 1" />
    <limit
      lower="-3"
      upper="3"
      effort="0"
      velocity="0" />
  </joint>

</robot>
