<?xml version="1.0"?>
<robot
  name="bed_and_environment_henry">
  <link
   name="autobed/base_link">
    <inertial>
      <origin
        xyz="1.07 3.94840580504828E-16 0.0837923121940762"
        rpy="0 0 0" />
      <mass
        value="6.1860172808288" />
      <inertia
        ixx="1.21978721906848"
        ixy="2.22044604925031E-15"
        ixz="-1.78284289885571E-15"
        iyy="7.15036992783298"
        iyz="-7.76907347784197E-16"
        izz="8.24641740321532" />
    </inertial>
    <visual>
      <origin
        xyz="0 0 0"
        rpy="0 0 0" />
      <geometry>
        <mesh
          filename="package://hrl_base_selection/urdf/bed_and_environment_henry/meshes/base_link.STL" />
      </geometry>
    </visual>
    <collision>
      <origin
        xyz="0 0 0"
        rpy="0 0 0" />
      <geometry>
        <mesh
          filename="package://hrl_base_selection/urdf/bed_and_environment_henry/meshes/base_link.STL" />
      </geometry>
    </collision>
  </link>

  <link
   name="autobed/bed_frame_link">
    <inertial>
      <origin
        xyz="1.20574977089702 -0.00197319632794563 0.010463658046454"
        rpy="0 0 0" />
      <mass
        value="298.525793737685" />
      <inertia
        ixx="25.3079805393988"
        ixy="0.124705215046845"
        ixz="-6.18752707469867"
        iyy="161.196265779885"
        iyz="0.0978345240222597"
        izz="178.196491872743" />
    </inertial>
    <visual>
      <origin
        xyz="0 0 0"
        rpy="0 0 0" />
      <geometry>
        <mesh
          filename="package://hrl_base_selection/urdf/bed_and_environment_henry/meshes/bed_frame_link.STL" />
      </geometry>
    </visual>
    <collision>
      <origin
        xyz="0 0 0"
        rpy="0 0 0" />
      <geometry>
        <mesh
          filename="package://hrl_base_selection/urdf/bed_and_environment_henry/meshes/bed_frame_link.STL" />
      </geometry>
    </collision>
  </link>
  <joint
   name="autobed/tele_legs_joint"
    type="prismatic">
    <origin
      xyz="-0.0400000000000005 0 0.320000000000001"
      rpy="0 0 0" />
    <parent
      link="autobed/base_link" />
    <child
      link="autobed/bed_frame_link" />
    <axis
      xyz="0 0 1" />
    <limit
      lower="-1"
      upper="1"
      effort="0"
      velocity="0" />
  </joint>
  <link
   name="autobed/leg_rest_upper">
    <inertial>
      <origin
        xyz="0.184999999999998 0.10500000000001 6.79804630482359E-16"
        rpy="0 0 0" />
      <mass
        value="71.0955000000001" />
      <inertia
        ixx="5.22152012812501"
        ixy="-3.21389401302034E-17"
        ixz="-3.22023131917487E-17"
        iyy="5.77132532812501"
        iyz="-2.87322532068486E-15"
        izz="1.072357125" />
    </inertial>
    <visual>
      <origin
        xyz="0 0 0"
        rpy="0 0 0" />
      <geometry>
        <mesh
          filename="package://hrl_base_selection/urdf/bed_and_environment_henry/meshes/leg_rest_upper.STL" />
      </geometry>
    </visual>
    <collision>
      <origin
        xyz="0 0 0"
        rpy="0 0 0" />
      <geometry>
        <mesh
          filename="package://hrl_base_selection/urdf/bed_and_environment_henry/meshes/leg_rest_upper.STL" />
      </geometry>
    </collision>
  </link>
  <joint
   name="autobed/leg_rest_upper_hinge"
    type="revolute">
    <origin
      xyz="1.075 0 0"
      rpy="1.5708 -1.8438E-16 7.6543E-16" />
    <parent
      link="autobed/bed_frame_link" />
    <child
      link="autobed/leg_rest_upper" />
    <axis
      xyz="0 0 1" />
    <limit
      lower="-2"
      upper="2"
      effort="0"
      velocity="0" />
  </joint>
  <link
   name="autobed/leg_rest_lower">
    <inertial>
      <origin
        xyz="0.325000000000004 0.104999999999987 -1.38760699713425E-16"
        rpy="0 0 0" />
      <mass
        value="124.8975" />
      <inertia
        ixx="9.172940765625"
        ixy="-4.25925024767052E-17"
        ixz="-8.25969319809873E-16"
        iyy="13.111375265625"
        iyz="2.10674154540826E-16"
        izz="4.856431125" />
    </inertial>
    <visual>
      <origin
        xyz="0 0 0"
        rpy="0 0 0" />
      <geometry>
        <mesh
          filename="package://hrl_base_selection/urdf/bed_and_environment_henry/meshes/leg_rest_lower.STL" />
      </geometry>
    </visual>
    <collision>
      <origin
        xyz="0 0 0"
        rpy="0 0 0" />
      <geometry>
        <mesh
          filename="package://hrl_base_selection/urdf/bed_and_environment_henry/meshes/leg_rest_lower.STL" />
      </geometry>
    </collision>
  </link>
  <joint
   name="autobed/leg_rest_lower_hinge"
    type="revolute">
    <origin
      xyz="0.37 0 0"
      rpy="8.4655E-16 -2.4744E-16 -1.8316E-16" />
    <parent
      link="autobed/leg_rest_upper" />
    <child
      link="autobed/leg_rest_lower" />
    <axis
      xyz="0 0 -1" />
    <limit
      lower="-2"
      upper="2"
      effort="0"
      velocity="0" />
  </joint>
  <link
   name="autobed/head_rest_link">
    <inertial>
      <origin
        xyz="0.338540021639504 -0.102807900235519 0.0331726512276706"
        rpy="0 0 0" />
      <mass
        value="158.265573279578" />
      <inertia
        ixx="13.8116841883572"
        ixy="0.366851813056848"
        ixz="-0.640983438566653"
        iyy="18.5647228773414"
        iyz="-0.857921499431992"
        izz="7.19318513198363" />
    </inertial>
    <visual>
      <origin
        xyz="0 0 0"
        rpy="0 0 0" />
      <geometry>
        <mesh
          filename="package://hrl_base_selection/urdf/bed_and_environment_henry/meshes/head_rest_link.STL" />
      </geometry>
    </visual>
    <collision>
      <origin
        xyz="0 0 0"
        rpy="0 0 0" />
      <geometry>
        <mesh
          filename="package://hrl_base_selection/urdf/bed_and_environment_henry/meshes/head_rest_link.STL" />
      </geometry>
    </collision>
  </link>
  <joint
   name="autobed/head_rest_hinge"
    type="revolute">
    <origin
      xyz="0.795 0 0.21"
      rpy="1.5708 0 -3.1416" />
    <parent
      link="autobed/bed_frame_link" />
    <child
      link="autobed/head_rest_link" />
    <axis
      xyz="0 0 1" />
    <limit
      lower="-2"
      upper="2"
      effort="0"
      velocity="0" />
  </joint>


</robot>